Workbook
Name nebulae: 'Nebulae & Cluster Sizes'!$A$2:$F$33
Name systems: 'Coordinates Conversion'!$A$2:$D$3177
Name ownership: Systems!$I$2:$AZ$3177

Sheet About
B1: Sarna Unified Cartography Kit (SUCKit aka SUCK)
B2: The kit is comprised of: | C2: Background:
A3: 1) | B3: Systems: indicates system coordinates and faction ownership in select years | C3: BattleTechWiki:System coordinates
A4: 2) | B4: Factions: contains the different factions in BattleTech, their assigned unique ID, colors assigned to them (for mapping purposes), foundation and dissolution years, and the number of systems they posses in a given year | C4: Discussion:
A5: 3) | B5: Pathfinding: jump route calculator based on available data | C5: BattleTechWiki talk:System coordinates
A6: 4) | B6: Coordinates Conversion: contains the raw coordinates from PDF sources and the formula for converting them to the base 2764 map orientation and scale
A7: 5) | B7: Nebulae & Cluster Sizes: contains the raw coordinates from PDF sources and the formula for converting them to the base 2764 map orientation and scale, as well as their scaled heights and widths based on current maps
A8: 6) | B8: Process Write-up: brief description of what went through each task that led to the output that you see before you
A9: 7) | B9: Credits: the people who have contributed to the SUCKit from its early years up to the present
A11: Version | B11: Changes | C11: Notes | D11: Updated by | E11: Sources used for update
A12: 2025.03.03 | B12: 1) Added faction ownership data from Handbook: House Marik 2571 map 2) Added faction ownership data from Handbook: House Liao 2571 map 3) Added faction ownership data from Handbook: House Davion 2571 map 4) Added faction ownership data from Handbook: House Kurita 2571 map 5) Added faction ownership data from Handbook: House Steiner 2571 map 6) Added MOC, OA faction ownership data from Handbook: Major Periphery States 2571 maps 7) Marked cells containing conflicting faction ownership data in Red. Entered best guess in the absence of official ruling 8) Renamed Dark Nebula in Systems sheet to Erit Cluster, using the coordinates of Dark Nebula 9) Restored 3030 faction data from a previous backup due to an overwrite error (still pending verification) 10) Corrected typo on start year of Vesper Marches and Malthus Confederation 11) Added more faction Sarna links | C12: 1) I need a long break 2) If anyone can cite sources and page numbers for start and end year of the various factions, I'd be forever grateful. I'm trying to trace back where I got some of the start years but am unable to find the sources | D12: Volt
A13: 2025.03.02 | B13: 1) Added faction ownership data from Handbook: House Kurita 2319 map 2) Added undiscovered faction ownership data source from Handbook: House Davion 2317 map and Handbook: House Marik 2271 map 3) Added faction ownership data from Handbook: House Steiner 2341 map 4) Renamed Tsamma | D13: Volt
A14: 2025.03.01 | B14: 1) Optimized some formulas in various sheets to reduce loading time 2) Corrected swapped height and width information on nebulae and clusters | D14: Volt
A15: 2025.02.04 | B15: 1) Updated faction ownership of various deep periphery systems based on actual available data (removed ambiguous assumptions) 2) Added faction ownership from Handbook: House Marik 2271 map 3) Added faction ownership from Handbook: House Davion 2317 map 4) Added faction ownerwhip from Handbook: House Liao 2367 map 5) Added Sarna links of factions 6) Updated ownership of affected systems from FS to FCF until 3063 7) Changed Chaos March to Independent from 3057-3068 and removed Chaos March as a faction 8) Added color coding to the faction ownership data. white cells are confirmed ownership data from maps or text, yellow are blank and assumed ownership status 9) Removed SLDF as a faction and restored TH faction ownership in 2783-2786 10) Changed I from Independent to Inhabited | C15: Reread Liberation of Terra vol 2 and corrected a mistake madde in the 2025.01.02 edit. Technically the FedCom ceased to be in 3067 when Yvonne declared the FedCom to be the FedSuns again. I restarted cleanup of the faction ownership data by going through all previous maps (and some sourcebook text I had access to, plus articless on Sarna of course) and decided to mark confirmed faction ownership in white and all assumed or interpolated date in yellow Incorporated updates from House Arano book (missed several faction ownership from maps) and maps from the BattleTech Universe Sourcebook | D15: Volt
A16: 2025.02.03 | B16: 1) Renamed Valencia (Nueva Castile) to Ascua (the star's name) 2) Renamed Rosetta to Ptolemy (the star's name) 3) Added Sarna link for Cielo 4) Major change to scaling formula for increased accuracy, affecting 125 systems, with the most significant impact on systems in the rimward periphery, particularly those in the Aurigan Reach 5) Merged Polybius and Appian 6) Jumps > 30LY in SIPS now appear as purple broken lines instead of solid lines to show viewer that the jump required intermediate jump points to reach the next system | C16: I decide to use statistical tools to modify my scaling and translation formulas. Before, I just used the average of the scales of the reference pairs, now I'm using the Least Squares method (a form of linear regression) to minimize measurement errors. Turns out Appian and Polybius are the same system. Initially thought it was two systems because some of the coordinates of the map from house Arano shifted around, which caused some confusion. | D16: Volt
A17: 2025.02.02 | B17: 1) Reduced the number of named ranges and amended the SIPS accordingly in order to reduce spreadsheet read iterations to further speed it up 2) Optimized SIPS extended jump pathfinding to skip over systems that bring the path farther from the destination if along the way an extended jump would be triggered anyway. Explanation in the Process Write-up sheet 3) Changed >30LY jump to evaluate all valid neighbors that fall within the criteria instead of just selecting the closest one in order to increase pathfinding flexibility. 4) Switched from A* pathfinding to Bidirectional A* pathfinding, reducing runtime by approximately 30% | C17: Okay, so I wasn't supposed to work on the SIPS anymore but I just happened to think of more optimizations to the code. I might design a flowchart (eventually) that better explains how the code works. | D17: Volt
A18: 2025.02.01 | B18: 1) Upgraded the SIPS to include pathfinding visualization. Now, whenever the Find Path button is clicked, a sidebar will appear after a path is found, which will show the entirety of the Inner Sphere and Deep Periphery without any borders, and a blue line that will connect the starting system to the destination system 2) Added SIPS menu bar item that will allow users to draw the map (without a path) and find a path. The menu bar item will appear as soon as the script is authorized by the user. | C18: It took me a couple of tries to get the pathfinding visualization to work, and apparently GAS will automatically deploy the visualization without any additional coding necessary on the file accessing the SIPS library. This might already be the final version of the SIPS as it is already a working tool. I do not know coding well enough to implement faction borders and different system sizes, but if anyone is willing to lend a hand, I'd appreciate it. | D18: Volt
A19: 2025.01.04 | B19: 1) Made minor corrections to Nebula & Clusters Sizes sheet 2) logic changes in SIPS pathfinding to improve performance 3) Deployed the SIPS as a library in Google Apps Script to make updating easier in case others would like to use the same script for other purposes 4) Merged changes from Volt's cleaned-up master copy to the Sarna official copy | C19: Apparently, dynamically searching for neighbors within 30LY is faster than using a cached list , so I eliminated the Neighbors sheet and modified the code to dynamically search for neighbors. | D19: Volt
A20: 2025.01.03 | B20: Completed the SUCKit Integrated Pathfinding Script (SIPS) | C20: After two months of work, the Pathfinding Script finally works. Users can set start and destination points and the script witll always find a path to connect the two systems. By default, the script will find the path with the fewest number of jumps, which also has the shortest total distance. Details on the SIPS can be found in the process write-up sheet. | D20: Volt
A21: 2025.01.02 | B21: 1) Added 3152 faction ownership from ilKhan's Eyes Only 2) Added faction ownership of Dark Nebula 3) Added Star League faction, changed the pre-2780 remote TH systems to SL 4) Added Star League Defense Force faction, changed the post-2780 TH systems to SLDF, and post-2780 remote TH systems to A 5) updated start and end year of some factions 6) removed faction ownership of deep periphery systems after 3095 for those that have not been mentioned since ISP3 | C21: Busy weekend since acquiring a copy of ilKhan's Eyes Only. Did a recheck of various entries, updated old ones and cleaned up some formulas. Because the Terran Hegemony ceased to exist after the Amaris Coup, I changed TH systems to SL and SLDF. All periphery systems after the dissolution of the SL were changed to Abandoned, and the TH worlds were changed to SLDF in 2783, and Independent in 2786 because by this time the Exodus had occurred. | D21: Volt
A22: 2025.01.01 | B22: 1) Added faction tags to systems with duplicate names to better identify them 2) Changed lookup for Pathfinding and distance calculation in Systems sheet from entering ID to entering system name to make the search more user-friendly | C22: I made the system selection based on the system name, made unique by adding faction tags to systems with duplicate names, instead of the system ID. Adding data validation by range also adds autocomplete so it makes typing up names easier | D22: Volt
A23: 2024.12.01 | B23: 1) Added Neighbors sheet in preparation for the SUCKit-Integrated Pathfinding Script (SIPS) 2) Added a Dark Nebula entry in systems to represent Erit Cluster and Camelot Command, both locations found within the nebula so that it can be a starting point or a destination later on once the SIPS is up and running. | C23: Working with ChatGPT (because I have not done any actual coding in over 25 years) to develop a pathfinding tool using Google Apps Script given the data in the SUCKit. But since GAS has a 6-min runtime limit I had to predetermine system neighbors to eliminate a lot of the iterative work. Was able to come up with a working script that would determine and record the system neighbors within 30LY. Initial version took around 70+ seconds to process everything, then I asked ChatGPT to optimize the code and it was able to trim the runtime down to about 10-11 seconds. I'm sure more optimizations can be done to speed up processing but I'll explore that when I have more free time. | D23: Volt
A24: 2024.11.01 | B24: 1) Added dissolution year of Republic of the Sphere 2) updated Sarna links to several systems 3) renamed Sonnia to Rahway and updated link 4) renamed Alpha Eridani to Achernar and updated link | D24: Volt
A25: 2023.06.02 | B25: 1) final cleanup of various sheets, interconnecting their content via formulas 2) changed version numbering to year.month.edit number 3) added pre-SUCKit changelog entries at the bottom of this page | D25: Volt
A26: 2023.06.01 | B26: 1) cleaned up the About page 2) cleaned up conditional formatting related to formula-bearing cells (gray) in various sheets and the distance Column to show Green for systems that are within 30LY and then Yellow going to Red for those beyond 30LY for easy reference 3) fixed some spelling errors 4) turned system size into a formula based on data on Nebulae & Cluster Sizes 5) removed 2271 to 2571, and 3030 | C26: Because of a potential data extraction issue carried over from the 2011.08.01 version of the faction ownership database, it is possible that some systems have been put under a certain affiliation but are actually not officially recognized. This is because faction ownership of systems that were obscured by pdf map borders from the various Handbook PDFs were included. As a result, the years from 2271 to 2571, and 3030 were removed until an updated faction ownership using corrected extraction procedures are retrieved. | D26: Volt
A27: 2023.03.02 | B27: Updated the Sarna Links of Alekseyevka and Badlands Cluster | D27: Volt
A28: 2023.03.01 | B28: 1) Corrected ownership of Rocky from HB:HK map and TtS: Rocky 2) Update the Sarna link of New Galicia | D28: Volt
A29: 2022.08.03 | B29: 1) Updated faction ownership of Crellacor in 3145 2) Updated Gustrell as Faction Capital beginning 3095 3) Updated faction ownership of Tamar Pact, Alyina Mercantile League, Arc-Royal Liberty Coalition and Vesper Marches systems in 3151 4) Changed Year Titles in Systems-Description and Systems sheets for better compatibility with the GUMS | C29: GUMS = Gruese's Ultimate Mapmaking Script, Sarna.net's preferred map generator | D29: Volt
A30: 2022.08.02 | B30: 1) Renamed Rodigo entry to the star's name, Alsace 2) Updated faction ownership of Joppa before 3067 | D30: Volt
A31: 2022.08.01 | B31: 1) Removed 14 systems erroneously included in the 3152 list that shouldn't be present because they are not visible in the maps 2) Swapped height and width of Caliban Nebula | D31: Volt
A32: 2022.07.02 | B32: 1) Coordinates for Cielo extracted and incorporated 2) Added Dalrymple (formerly abandoned Tintavel) | D32: Volt
A33: 2022.07.01 | B33: 1) Qualip marked abandoned in 2864 2) Renamed Kandersteg to Matahari 3) Updated Faction Ownership of Matahari, Gibraltar, Sadurni and Gienah before 2750 4) Extended Scorpion Empire systems Ownership to 3152 5) Updated Faction Ownership of Bolan in 2367 6) Added new system Cielo (Coordinates to follow) 7) Added The Institute (formerly abandoned New Galicia) | D33: Volt
A34: 2022.03.01 | B34: 1) Changed Faction Ownership of Arcturus, Blue Diamond, Kelenfold, Borghese and Kerensky's Vision in 3151 2) Changed Sarna link of Almotacen | D34: Volt
A35: 2022.01.01 | B35: 1) Added faction ownership of systems appearing in Tamar Rising maps 2) updated coordinates of Matteo based on PDF map raw data 3) removed non-canon label of Matteo faction ownership on all periods before 3151 4) added placeholder Sarna link for Matteo 5) added new factions from Tamar Rising | C35: thanks to Hammer from the MegaMek team for sharing their data from mining the content of Tamar Rising. Their file effectively cut the work of the SUCS in half by identifying the faction ownership of the systems that appeared on the maps, allowing us to devote our time to identifying ownership changes, abandoned systems, reappeared and new systems, and coordinates extraction. | D35: Volt
A36: 2021.10.01 | B36: Updated the Sarna link of Dieudonné | C36: special thanks to Nic Jansma | D36: Volt
A37: 2021.09.02 | B37: Renamed the descriptions of 3135, 3145 and 3151 in the Systems-Description sheet | C37: Got lazy and just wrote "Dark Age" before | D37: Volt
A38: 2021.09.01 | B38: Fixed incorrect description in the Systems-Description sheet | C38: Thanks, Revanche! | D38: Volt
A39: 2021.08.02 | B39: Fixed incorrect column labels in the Systems-Description sheet | C39: Thanks, gruese! | D39: Volt
A40: 2021.08.01 | B40: 1) Updated the Sarna links to some systems 2) renamed Alnasi to Gamma Sagittarius for consistency with Sarna.net | C40: 1) thanks, Nic! 2) BTW, Alnasi should have been Alnasl, typo error | D40: Volt
A41: 2021.07.06 | B41: Changed name merge formula in Coordinates Conversion sheet from vlookup to index-match-match | D41: Volt
...

Sheet Systems Sheet Description
A1: Column | B1: Title | C1: Description
A2: =iferror(right(left(address(1,match($B2,Systems!$2:$2,)),2),1),"") -> A | B2: {=transpose(Systems!$2:$2)} -> systemId | C2: unique system ID number (because some systems have duplicate names)
A3: =iferror(right(left(address(1,match($B3,Systems!$2:$2,)),2),1),"") -> B | B3: systemName | C3: Name of the System
A4: =iferror(right(left(address(1,match($B4,Systems!$2:$2,)),2),1),"") -> C | B4: alternateName | C4: Alternate names of the system, name changes (with year), and/or notable worlds within the system
A5: =iferror(right(left(address(1,match($B5,Systems!$2:$2,)),2),1),"") -> D | B5: x | C5: X-ordinate for mapping purposes as extracted from official maps
A6: =iferror(right(left(address(1,match($B6,Systems!$2:$2,)),2),1),"") -> E | B6: y | C6: y-ordinate for mapping purposes as extracted from official maps
A7: =iferror(right(left(address(1,match($B7,Systems!$2:$2,)),2),1),"") -> F | B7: size | C7: reference size (in LY) of a system/cluster for mapping purposes, [width,height,rotation]. Widths and heights are from center to edge, not edge to edge
A8: =iferror(right(left(address(1,match($B8,Systems!$2:$2,)),2),1),"") -> G | B8: sarnaLink | C8: URL of the entry in www.sarna.net
A9: =iferror(right(left(address(1,match($B9,Systems!$2:$2,)),2),1),"") -> H | B9: distance (LY) | C9: based on the coordinates, the linear distance of the system from a reference point indicated in cell H1 (Sol by default)
B10: 2271 | C10: Free Worlds League Founding | D10: [35019] Handbook: House Marik
B11: 2317 | C11: Federated Suns Founding | D11: [35024] Handbook: House Davion
B12: 2319 | C12: Draconis Combine Founding | D12: [35205] Handbook: House Kurita
B13: 2341 | C13: Lyran Commonwealth Founding | D13: [35001] Handbook: House Steiner
B14: 2366 | C14: Capellan Confederation Founding | D14: [35204] Handbook: House Liao
B15: 2571 | C15: Star League Founding | D15: [35019] Handbook: House Marik [35204] Handbook: House Liao [35024] Handbook: House Davion [35205] Handbook: House Kurita [35001] Handbook: House Steiner [35203] Handbook: Major Periphery States
B16: 2596 | C16: End of Reunification War | D16: [35231] Historical: Reunification War
B17: 2750 | C17: Beginning of the Fall of the Star League | D17: [35222] Era Report: 2750
B18: 2765 | C18: Eve of the Amaris Coup | D18: [35232] Historical: Liberation of Terra volume 1 [35SN501] House Arano: The Aurigan Coalition [35702] BattleTech Universe
B19: 2767 | C19: Amaris Empire | D19: 2765 map with the core TH worlds shifted to AE because of the Coup
B20: 2783 | C20: Great House Annexations of the remnants of the Terran Hegemony | D20: [35233] Historical: Liberation of Terra volume 2
B21: 2786 | C21: Start of 1st Succession War & Settlement of Pentagon | D21: [35230] Historical: Operation Klondike [35233] Historical: Liberation of Terra volume 2 [35702] BattleTech Universe
... B26: 3025 | C26: End of 3rd Succession War | D26: Inner Sphere at War 3025 PDF map [35SN501] House Arano: The Aurigan Coalition [35702] BattleTech Universe
B27: 3030 | C27: End of 4th Succession War
B28: 3040 | C28: End of War of 3039 | D28: [35014] Historical: War of 3039
B29: 3049 | C29: Operation Revival: Periphery Action | D29: [35230] Era Report: 3052
B30: 3050a | C30: Operation Revival: Wave 1 | D30: [35230] Era Report: 3052
B31: 3050b | C31: Operation Revival: Wave 2 | D31: [35230] Era Report: 3052
B32: 3050c | C32: Operation Revival: Wave 3 | D32: [35230] Era Report: 3052
B33: 3051 | C33: Operation Revival: Wave 4 / Year of Peace | D33: [35230] Era Report: 3052
B34: 3052 | C34: Operation Revival: Wave 5 / End of Operation Revival | D34: [35230] Era Report: 3052
B35: 3057 | C35: Start of Operation Guerrero | D35: [35221] Era Report: 3062, but reflecting the formation of the Lyran Alliance while keeping the FedCom march divisions
B36: 3058 | C36: End of Operation Guerrero | D36: [35221] Era Report: 3062 reflecting the formation of the Chaos March, and Lyran Alliance having the Provincial divisions
B37: 3059a | C37: Operation Bulldog: Wave 1 | D37: [35221] Era Report: 3062
B38: 3059b | C38: Operation Bulldog: Wave 2 | D38: [35221] Era Report: 3062
B39: 3059c | C39: Operation Bulldog: Wave 3 | D39: [35221] Era Report: 3062
B40: 3059d | C40: Operation Bulldog: Wave 4 | D40: [35221] Era Report: 3062
B41: 3063 | C41: Start of FC Civil War | D41: [35221] Era Report: 3062
B42: 3067 | C42: End of FC Civil War | D42: [35307] Jihad: Final Reckoning
B43: 3068 | C43: Start of WB Jihad | D43: 3067 map with the WoB Protectorate
B44: 3075 | C44: Middle of the WoB Jihad | D44: [35303] Jihad Secrets: The Blake Documents
...

Sheet Systems
C1: Systems Count : | D1: =COUNTA(B3:B3178) -> 3175 | F1: Reference System : | G1: Sol [Terra, Luna, Mars] | H1: {=INDEX(systems,MATCH(G1,INDEX(systems,0,2),),1)} -> 2370 | I1: =counta(I3:I3178)/$D$1 -> 0.64724409 | J1: =counta(J3:J3178)/$D$1 -> 0.62834646 | K1: =counta(K3:K3178)/$D$1 -> 0.64944882 | L1: =counta(L3:L3178)/$D$1 -> 0.59370079 | M1: =counta(M3:M3178)/$D$1 -> 0.64314961 | N1: =counta(N3:N3178)/$D$1 -> 0.90519685 | O1: =counta(O3:O3178)/$D$1 -> 0.52850394 | P1: =counta(P3:P3178)/$D$1 -> 0.99338583 | ... AZ1: =counta(AZ3:AZ3178)/$D$1 -> 0.95086614
A2: systemId | B2: systemName | C2: alternateName | D2: x | E2: y | F2: size | G2: sarnaLink | H2: distance (LY) | I2: 2271 | J2: 2317 | K2: 2319 | L2: 2341 | M2: 2366 | N2: 2571 | O2: 2596 | P2: 2750 | Q2: 2765 | R2: 2767 | S2: 2783 | T2: 2786 | U2: 2821 | V2: 2822 | W2: 2830 | X2: 2864 | Y2: 3025 | Z2: 3030 | AA2: 3040 | AB2: 3049 | AC2: 3050a | AD2: 3050b | AE2: 3050c | AF2: 3051 | AG2: 3052 | AH2: 3057 | AI2: 3058 | AJ2: 3059a | AK2: 3059b | AL2: 3059c | AM2: 3059d | AN2: 3063 | AO2: 3067 | AP2: 3068 | AQ2: 3075 | AR2: 3079 | AS2: 3081 | AT2: 3085 | AU2: 3095 | AV2: 3130 | AW2: 3135 | AX2: 3145 | AY2: 3151 | AZ2: 3152
A3: 1 | B3: A Place | D3: {=index(systems,match($A3,INDEX(systems,0,1),),3)} -> -123.764 | E3: {=index(systems,match($A3,INDEX(systems,0,1),),4)} -> 272.182 | F3: =IFERROR(__xludf.DUMMYFUNCTION("let(row, match($B3&if($C3<>"""","" [""&$C3&""]"",""""),index(nebulae,,2),0),join("","",iferror(round(index(nebulae,row,5)/2,3),1),iferror(round(index(nebulae,row,6)/2,3),1),0))"),"1,1,0") -> 1,1,0 | G3: https://www.sarna.net/wiki/A_Place | H3: {=let(systemId,match(A3,index(systems,0,1),),refSystemId,match($H$1,index(systems,0,1),),x,index(systems,systemId,3),y,index(systems,systemId,4),refX,index(systems,refSystemId,3),refY,index(systems,refSystemId,4),round(sqrt((x-refX)^2+(y-refY)^2),3))} -> 298.999 | I3: U | J3: U | K3: U | L3: U | M3: U | N3: U | P3: LC,Tamar Pact,Tamar Domains | Q3: LC,Tamar Pact,Tamar Domains | R3: LC,Tamar Pact,Tamar Domains | S3: LC,Tamar Pact,Tamar Domains | T3: LC,Tamar Pact,Tamar Domains | U3: LC,Tamar Pact,Tamar Domains | V3: LC,Tamar Pact,Tamar Domains | W3: LC,Tamar Pact,Tamar Domains | X3: LC,Tamar Pact,Tamar Domains | Y3: LC,Tamar Pact,Tamar Domains | Z3: LC,Tamar Pact,Tamar Domains | AA3: FCL,Tamar March,Benfled Operational Area,Region 2 | AB3: FCL,Tamar March,Benfled Operational Area,Region 2 | AC3: FCL,Tamar March,Benfled Operational Area,Region 2 | AD3: FCL,Tamar March,Benfled Operational Area,Region 2 | AE3: FCL,Tamar March,Benfled Operational Area,Region 2 | AF3: FCL,Tamar March,Benfled Operational Area,Region 2 | AG3: FCL,Tamar March,Pandora Operational Area,Region 1 | AH3: LA,Tamar March,Pandora Operational Area,Region 1 | AI3: LA,Donegal Province,Pandora Theater,Arc-Royal Defense Cordon | AJ3: LA,Donegal Province,Pandora Theater,Arc-Royal Defense Cordon | AK3: LA,Donegal Province,Pandora Theater,Arc-Royal Defense Cordon | AL3: LA,Donegal Province,Pandora Theater,Arc-Royal Defense Cordon | AM3: LA,Donegal Province,Pandora Theater,Arc-Royal Defense Cordon | AN3: LA,Donegal Province,Pandora Theater,Arc-Royal Defense Cordon | AO3: LA,Arc-Royal Theater | AP3: LA,Arc-Royal Theater | AQ3: LA,Arc-Royal Theater | AR3: LA,Arc-Royal Theater | AS3: LA,Arc-Royal Theater | AT3: LC,Arc-Royal Theater | AU3: LC,Arc-Royal Theater | AV3: D(LC,CJF) | AW3: D(LC,CJF) | AX3: CJF | AY3: CJF | AZ3: I
A4: 2 | B4: Aalzorg | D4: {=index(systems,match($A4,INDEX(systems,0,1),),3)} -> 583.881 | E4: {=index(systems,match($A4,INDEX(systems,0,1),),4)} -> 256.931 | F4: =IFERROR(__xludf.DUMMYFUNCTION("let(row, match($B4&if($C4<>"""","" [""&$C4&""]"",""""),index(nebulae,,2),0),join("","",iferror(round(index(nebulae,row,5)/2,3),1),iferror(round(index(nebulae,row,6)/2,3),1),0))"),"1,1,0") -> 1,1,0 | G4: https://www.sarna.net/wiki/Aalzorg | H4: {=let(systemId,match(A4,index(systems,0,1),),refSystemId,match($H$1,index(systems,0,1),),x,index(systems,systemId,3),y,index(systems,systemId,4),refX,index(systems,refSystemId,3),refY,index(systems,refSystemId,4),round(sqrt((x-refX)^2+(y-refY)^2),3))} -> 637.911 | I4: U | J4: U | K4: U | L4: U | M4: U | N4: U | P4: OA,Traders Domain | Q4: OA,Traders Domain | R4: OA,Traders Domain | S4: OA,Traders Domain | T4: OA,Traders Domain | U4: A | V4: A | W4: A | X4: A | Y4: A | Z4: A | AA4: A | AB4: A | AC4: A | AD4: A | AE4: A | AF4: A | AG4: A | AH4: A | AI4: A | AJ4: A | AK4: A | AL4: A | AM4: A | AN4: A | AO4: A | AP4: A | AQ4: A | AR4: A | AS4: A | AT4: A | AU4: A | AV4: A | AW4: A | AX4: A | AY4: A | AZ4: OW,Traders Domain
A5: 3 | B5: Abadan | D5: {=index(systems,match($A5,INDEX(systems,0,1),),3)} -> -70.319 | E5: {=index(systems,match($A5,INDEX(systems,0,1),),4)} -> -95.949 | F5: =IFERROR(__xludf.DUMMYFUNCTION("let(row, match($B5&if($C5<>"""","" [""&$C5&""]"",""""),index(nebulae,,2),0),join("","",iferror(round(index(nebulae,row,5)/2,3),1),iferror(round(index(nebulae,row,6)/2,3),1),0))"),"1,1,0") -> 1,1,0 | G5: https://www.sarna.net/wiki/Abadan | H5: {=let(systemId,match(A5,index(systems,0,1),),refSystemId,match($H$1,index(systems,0,1),),x,index(systems,systemId,3),y,index(systems,systemId,4),refX,index(systems,refSystemId,3),refY,index(systems,refSystemId,4),round(sqrt((x-refX)^2+(y-refY)^2),3))} -> 118.958 | I5: MCM | J5: FWL,Marik Commonwealth | K5: FWL,Marik Commonwealth | L5: FWL,Marik Commonwealth | M5: FWL,Marik Commonwealth | N5: FWL,Marik Commonwealth | O5: FWL,Marik Commonwealth | P5: FWL,Marik Commonwealth | Q5: FWL,Marik Commonwealth | R5: FWL,Marik Commonwealth | S5: FWL,Marik Commonwealth | T5: FWL,Marik Commonwealth | U5: FWL,Marik Commonwealth | V5: FWL,Marik Commonwealth | W5: FWL,Marik Commonwealth | X5: FWL,Marik Commonwealth | Y5: FWL,Marik Commonwealth | Z5: FWL,Marik Commonwealth | AA5: FWL,Marik Commonwealth | AB5: FWL,Marik Commonwealth | AC5: FWL,Marik Commonwealth | AD5: FWL,Marik Commonwealth | AE5: FWL,Marik Commonwealth | AF5: FWL,Marik Commonwealth | AG5: FWL,Marik Commonwealth | AH5: FWL,Marik Commonwealth | AI5: FWL,Marik Commonwealth | AJ5: FWL,Marik Commonwealth | AK5: FWL,Marik Commonwealth | AL5: FWL,Marik Commonwealth | AM5: FWL,Marik Commonwealth | AN5: FWL,Marik Commonwealth | AO5: FWL,Marik Commonwealth | AP5: FWL,Marik Commonwealth | AQ5: FWL,Marik Commonwealth | AR5: MCM | AS5: MCM | AT5: RS,Prefecture VII | AU5: RS,Prefecture VII | AV5: RS,Prefecture VII | AW5: I | AX5: FWL,Clan Protectorate | AY5: FWL,Clan Protectorate | AZ5: FWL,Clan Protectorate
A6: 4 | B6: Abagnar | D6: {=index(systems,match($A6,INDEX(systems,0,1),),3)} -> 380.231 | E6: {=index(systems,match($A6,INDEX(systems,0,1),),4)} -> 314.823 | F6: =IFERROR(__xludf.DUMMYFUNCTION("let(row, match($B6&if($C6<>"""","" [""&$C6&""]"",""""),index(nebulae,,2),0),join("","",iferror(round(index(nebulae,row,5)/2,3),1),iferror(round(index(nebulae,row,6)/2,3),1),0))"),"1,1,0") -> 1,1,0 | G6: https://www.sarna.net/wiki/Abagnar | H6: {=let(systemId,match(A6,index(systems,0,1),),refSystemId,match($H$1,index(systems,0,1),),x,index(systems,systemId,3),y,index(systems,systemId,4),refX,index(systems,refSystemId,3),refY,index(systems,refSystemId,4),round(sqrt((x-refX)^2+(y-refY)^2),3))} -> 493.649 | I6: U | J6: U | K6: U | L6: U | M6: U | N6: U | P6: DC,Pesht Military District,Ningxia Prefecture | Q6: DC,Pesht Military District,Ningxia Prefecture | R6: DC,Pesht Military District,Ningxia Prefecture | S6: DC,Pesht Military District,Ningxia Prefecture | T6: DC,Pesht Military District,Ningxia Prefecture | U6: DC,Pesht Military District,Ningxia Prefecture | V6: DC,Pesht Military District,Ningxia Prefecture | W6: DC,Pesht Military District,Ningxia Prefecture | X6: DC,Pesht Military District,Ningxia Prefecture | Y6: DC,Pesht Military District,Ningxia Prefecture | Z6: DC,Pesht Military District,Ningxia Prefecture | AA6: DC,Pesht Military District,Ningxia Prefecture | AB6: DC,Pesht Military District,Ningxia Prefecture | AC6: DC,Pesht Military District,Ningxia Prefecture | AD6: DC,Pesht Military District,Ningxia Prefecture | AE6: DC,Pesht Military District,Ningxia Prefecture | AF6: DC,Pesht Military District,Ningxia Prefecture | AG6: DC,Pesht Military District,Ningxia Prefecture | AH6: DC,Pesht Military District,Ningxia Prefecture | AI6: DC,Pesht Military District,Ningxia Prefecture | AJ6: DC,Pesht Military District,Ningxia Prefecture | AK6: DC,Pesht Military District,Ningxia Prefecture | AL6: DC,Pesht Military District,Ningxia Prefecture | AM6: DC,Pesht Military District,Ningxia Prefecture | AN6: DC,Pesht Military District,Ningxia Prefecture | AO6: DC,Pesht Military District,Ningxia Prefecture | AP6: DC,Pesht Military District,Ningxia Prefecture | AQ6: DC,Pesht Military District,Ningxia Prefecture | AR6: DC,Pesht Military District,Ningxia Prefecture | AS6: DC,Pesht Military District,Ningxia Prefecture | AT6: DC,Pesht Military District,Ningxia Prefecture | AU6: DC,Pesht Military District,Ningxia Prefecture | AV6: DC,Pesht Military District,Ningxia Prefecture | AW6: DC,Pesht Military District,Ningxia Prefecture | AX6: DC,Pesht Military District,Ningxia Prefecture | AY6: DC,Pesht Military District,Ningxia Prefecture | AZ6: DC,Pesht Military District,Ningxia Prefecture
A7: 5 | B7: Abbadiyah | D7: {=index(systems,match($A7,INDEX(systems,0,1),),3)} -> -317.967 | E7: {=index(systems,match($A7,INDEX(systems,0,1),),4)} -> 246.551 | F7: =IFERROR(__xludf.DUMMYFUNCTION("let(row, match($B7&if($C7<>"""","" [""&$C7&""]"",""""),index(nebulae,,2),0),join("","",iferror(round(index(nebulae,row,5)/2,3),1),iferror(round(index(nebulae,row,6)/2,3),1),0))"),"1,1,0") -> 1,1,0 | G7: https://www.sarna.net/wiki/Abbadiyah | H7: {=let(systemId,match(A7,index(systems,0,1),),refSystemId,match($H$1,index(systems,0,1),),x,index(systems,systemId,3),y,index(systems,systemId,4),refX,index(systems,refSystemId,3),refY,index(systems,refSystemId,4),round(sqrt((x-refX)^2+(y-refY)^2),3))} -> 402.356 | N7: LC,Protectorate of Donegal,Coventry Province | O7: LC,Protectorate of Donegal,Coventry Province | P7: LC,Protectorate of Donegal,Coventry Province | Q7: LC,Protectorate of Donegal,Coventry Province | R7: LC,Protectorate of Donegal,Coventry Province | S7: LC,Protectorate of Donegal,Coventry Province | T7: LC,Protectorate of Donegal,Coventry Province | U7: LC,Protectorate of Donegal,Coventry Province | V7: LC,Protectorate of Donegal,Coventry Province | W7: LC,Protectorate of Donegal,Coventry Province | X7: LC,Protectorate of Donegal,Coventry Province | Y7: LC,Protectorate of Donegal,Coventry Province | Z7: LC,Protectorate of Donegal,Coventry Province | AA7: FCL,Donegal March,Coventry Operational Area,Region 2 | AB7: FCL,Donegal March,Coventry Operational Area,Region 2 | AC7: FCL,Donegal March,Coventry Operational Area,Region 2 | AD7: FCL,Donegal March,Coventry Operational Area,Region 2 | AE7: FCL,Donegal March,Coventry Operational Area,Region 2 | AF7: FCL,Donegal March,Coventry Operational Area,Region 2 | AG7: FCL,Donegal March,Coventry Operational Area,Region 2 | AH7: LA,Donegal March,Coventry Operational Area,Region 2 | AI7: LA,Coventry Province | AJ7: LA,Coventry Province | AK7: LA,Coventry Province | AL7: LA,Coventry Province | AM7: LA,Coventry Province | AN7: LA,Coventry Province | AO7: LA,Coventry Province | AP7: LA,Coventry Province | AQ7: LA,Coventry Province | AR7: LA,Coventry Province | AS7: LA,Coventry Province | AT7: LC,Coventry Province | AU7: LC,Coventry Province | AV7: LC,Coventry Province | AW7: LC,Coventry Province | AX7: LC,Coventry Province | AY7: LC,Coventry Province | AZ7: LC,Coventry Province
A8: 6 | B8: Abbeville | D8: {=index(systems,match($A8,INDEX(systems,0,1),),3)} -> 605.903 | E8: {=index(systems,match($A8,INDEX(systems,0,1),),4)} -> -39.852 | F8: =IFERROR(__xludf.DUMMYFUNCTION("let(row, match($B8&if($C8<>"""","" [""&$C8&""]"",""""),index(nebulae,,2),0),join("","",iferror(round(index(nebulae,row,5)/2,3),1),iferror(round(index(nebulae,row,6)/2,3),1),0))"),"1,1,0") -> 1,1,0 | G8: https://www.sarna.net/wiki/Abbeville | H8: {=let(systemId,match(A8,index(systems,0,1),),refSystemId,match($H$1,index(systems,0,1),),x,index(systems,systemId,3),y,index(systems,systemId,4),refX,index(systems,refSystemId,3),refY,index(systems,refSystemId,4),round(sqrt((x-refX)^2+(y-refY)^2),3))} -> 607.212 | N8: FS,Draconis March,Woodbine Operational Area,Region 2 | O8: FS,Draconis March,Woodbine Operational Area,Region 2 | P8: FS,Draconis March,Woodbine Operational Area,Region 2 | Q8: FS,Draconis March,Woodbine Operational Area,Region 2 | R8: FS,Draconis March,Woodbine Operational Area,Region 2 | S8: FS,Draconis March,Woodbine Operational Area,Region 2 | T8: FS,Draconis March,Woodbine Operational Area,Region 2 | U8: FS,Draconis March,Woodbine Operational Area,Region 4 | V8: FS,Draconis March,Woodbine Operational Area,Region 4 | W8: FS,Draconis March,Woodbine Operational Area,Region 4 | X8: FS,Draconis March,Woodbine Operational Area,Region 4 | Y8: FS,Draconis March,Woodbine Operational Area,Kilbourne PDZ | Z8: FS,Draconis March,Woodbine Operational Area,Kilbourne PDZ | AA8: FCF,Draconis March,Woodbine Operational Area,Kilbourne PDZ | AB8: FCF,Draconis March,Woodbine Operational Area,Kilbourne PDZ | AC8: FCF,Draconis March,Woodbine Operational Area,Kilbourne PDZ | AD8: FCF,Draconis March,Woodbine Operational Area,Kilbourne PDZ | AE8: FCF,Draconis March,Woodbine Operational Area,Kilbourne PDZ | AF8: FCF,Draconis March,Woodbine Operational Area,Kilbourne PDZ | AG8: FCF,Draconis March,Woodbine Operational Area,Kilbourne PDZ | AH8: FCF,Draconis March,Woodbine Operational Area,Kilbourne PDZ | AI8: FCF,Draconis March,Woodbine Operational Area,Kilbourne PDZ | AJ8: FCF,Draconis March,Woodbine Operational Area,Kilbourne PDZ | AK8: FCF,Draconis March,Woodbine Operational Area,Kilbourne PDZ | AL8: FCF,Draconis March,Woodbine Operational Area,Kilbourne PDZ | AM8: FCF,Draconis March,Woodbine Operational Area,Kilbourne PDZ | AN8: FCF,Draconis March,Woodbine Operational Area,Kilbourne PDZ | AO8: FS,Draconis March,Woodbine Operational Area,Kilbourne PDZ | AP8: FS,Draconis March,Woodbine Operational Area,Kilbourne PDZ | AQ8: FS,Draconis March,Woodbine Operational Area,Kilbourne PDZ | AR8: FS,Periphery March,Woodbine Operational Area,Kilbourne PDZ | AS8: FS,Periphery March,Woodbine Operational Area,Kilbourne PDZ | AT8: FS,Periphery March,Woodbine Operational Area,Kilbourne PDZ | AU8: FS,Periphery March,Woodbine Operational Area,Kilbourne PDZ | AV8: FS,Periphery March,Woodbine Operational Area,Kilbourne PDZ | AW8: FS,Periphery March,Woodbine Operational Area,Kilbourne PDZ | AX8: FS,Periphery March,Woodbine Operational Area,Kilbourne PDZ | AY8: FS,Periphery March,Woodbine Operational Area,Kilbourne PDZ | AZ8: FS,Periphery March,Woodbine Operational Area,Kilbourne PDZ
A9: 7 | B9: Abejorral | D9: {=index(systems,match($A9,INDEX(systems,0,1),),3)} -> -299.341 | E9: {=index(systems,match($A9,INDEX(systems,0,1),),4)} -> 127.388 | F9: =IFERROR(__xludf.DUMMYFUNCTION("let(row, match($B9&if($C9<>"""","" [""&$C9&""]"",""""),index(nebulae,,2),0),join("","",iferror(round(index(nebulae,row,5)/2,3),1),iferror(round(index(nebulae,row,6)/2,3),1),0))"),"1,1,0") -> 1,1,0 | G9: https://www.sarna.net/wiki/Abejorral | H9: {=let(systemId,match(A9,index(systems,0,1),),refSystemId,match($H$1,index(systems,0,1),),x,index(systems,systemId,3),y,index(systems,systemId,4),refX,index(systems,refSystemId,3),refY,index(systems,refSystemId,4),round(sqrt((x-refX)^2+(y-refY)^2),3))} -> 325.319 | I9: U | J9: U | K9: U | L9: U | M9: U | N9: U | P9: LC,Protectorate of Donegal,Alarion Province | Q9: LC,Protectorate of Donegal,Alarion Province | R9: LC,Protectorate of Donegal,Alarion Province | S9: LC,Protectorate of Donegal,Alarion Province | T9: LC,Protectorate of Donegal,Alarion Province | U9: LC,Protectorate of Donegal,Alarion Province | V9: LC,Protectorate of Donegal,Alarion Province | W9: LC,Protectorate of Donegal,Alarion Province | X9: LC,Protectorate of Donegal,Alarion Province | Y9: LC,Protectorate of Donegal,Alarion Province | Z9: LC,Protectorate of Donegal,Alarion Province | AA9: FCL,Donegal March,Alarion Operational Area,Region 1 | AB9: FCL,Donegal March,Alarion Operational Area,Region 1 | AC9: FCL,Donegal March,Alarion Operational Area,Region 1 | AD9: FCL,Donegal March,Alarion Operational Area,Region 1 | AE9: FCL,Donegal March,Alarion Operational Area,Region 1 | AF9: FCL,Donegal March,Alarion Operational Area,Region 1 | AG9: FCL,Donegal March,Alarion Operational Area,Region 1 | AH9: LA,Donegal March,Alarion Operational Area,Region 1 | AI9: LA,Alarion Province | AJ9: LA,Alarion Province | AK9: LA,Alarion Province | AL9: LA,Alarion Province | AM9: LA,Alarion Province | AN9: LA,Alarion Province | AO9: LA,Alarion Province | AP9: LA,Alarion Province | AQ9: LA,Alarion Province | AR9: LA,Alarion Province | AS9: LA,Buena Province | AT9: LC,Buena Province | AU9: LC,Buena Province | AV9: LC,Buena Province | AW9: LC,Buena Province | AX9: LC,Buena Province | AY9: LC,Buena Province | AZ9: LC,Bolan Province
A10: 3146 | B10: Abeline | C10: Taygete (2890+) | D10: {=index(systems,match($A10,INDEX(systems,0,1),),3)} -> -26.218 | E10: {=index(systems,match($A10,INDEX(systems,0,1),),4)} -> -481.285 | F10: =IFERROR(__xludf.DUMMYFUNCTION("let(row, match($B10&if($C10<>"""","" [""&$C10&""]"",""""),index(nebulae,,2),0),join("","",iferror(round(index(nebulae,row,5)/2,3),1),iferror(round(index(nebulae,row,6)/2,3),1),0))"),"1,1,0") -> 1,1,0 | G10: https://www.sarna.net/wiki/Taygete | H10: {=let(systemId,match(A10,index(systems,0,1),),refSystemId,match($H$1,index(systems,0,1),),x,index(systems,systemId,3),y,index(systems,systemId,4),refX,index(systems,refSystemId,3),refY,index(systems,refSystemId,4),round(sqrt((x-refX)^2+(y-refY)^2),3))} -> 481.999 | I10: U | J10: U | K10: U | L10: U | M10: U | N10: U | P10: U | Q10: U | R10: U | S10: U | T10: U | V10: I | W10: I | X10: I | Y10: A | Z10: A | AA10: A | AB10: A | AC10: A | AD10: A | AE10: A | AF10: A | AG10: A | AH10: A | AI10: A | AJ10: A | AK10: A | AL10: A | AM10: A | AN10: A | AO10: A | AP10: A | AQ10: A | AR10: A | AS10: A | AT10: A | AU10: A | AV10: A | AW10: A | AX10: A | AY10: A | AZ10: A
A11: 8 | B11: Aberystwyth | D11: {=index(systems,match($A11,INDEX(systems,0,1),),3)} -> -430.967 | E11: {=index(systems,match($A11,INDEX(systems,0,1),),4)} -> 58.633 | F11: =IFERROR(__xludf.DUMMYFUNCTION("let(row, match($B11&if($C11<>"""","" [""&$C11&""]"",""""),index(nebulae,,2),0),join("","",iferror(round(index(nebulae,row,5)/2,3),1),iferror(round(index(nebulae,row,6)/2,3),1),0))"),"1,1,0") -> 1,1,0 | G11: https://www.sarna.net/wiki/Aberystwyth | H11: {=let(systemId,match(A11,index(systems,0,1),),refSystemId,match($H$1,index(systems,0,1),),x,index(systems,systemId,3),y,index(systems,systemId,4),refX,index(systems,refSystemId,3),refY,index(systems,refSystemId,4),round(sqrt((x-refX)^2+(y-refY)^2),3))} -> 434.937 | I11: U | J11: U | K11: U | L11: U | M11: U | N11: U | P11: RW,Timbuktu Province | Q11: RW,Timbuktu Province | R11: RW,Timbuktu Province | S11: LC,Protectorate of Donegal,Alarion Province | T11: LC,Protectorate of Donegal,Alarion Province | U11: LC,Protectorate of Donegal,Alarion Province | V11: LC,Protectorate of Donegal,Alarion Province | W11: LC,Protectorate of Donegal,Alarion Province | X11: LC,Protectorate of Donegal,Alarion Province | Y11: LC,Protectorate of Donegal,Alarion Province | Z11: LC,Protectorate of Donegal,Alarion Province | AA11: FCL,Periphery March,Venaria Operational Area,Region 2 | AB11: FCL,Periphery March,Venaria Operational Area,Region 2 | AC11: FCL,Periphery March,Venaria Operational Area,Region 2 | AD11: FCL,Periphery March,Venaria Operational Area,Region 2 | AE11: FCL,Periphery March,Venaria Operational Area,Region 2 | AF11: FCL,Periphery March,Venaria Operational Area,Region 2 | AG11: FCL,Periphery March,Venaria Operational Area,Region 2 | AH11: LA,Periphery March,Venaria Operational Area,Region 2 | AI11: LA,Alarion Province,Timbuktu Theater | AJ11: LA,Alarion Province,Timbuktu Theater | AK11: LA,Alarion Province,Timbuktu Theater | AL11: LA,Alarion Province,Timbuktu Theater | AM11: LA,Alarion Province,Timbuktu Theater | AN11: LA,Alarion Province,Timbuktu Theater | AO11: LA,Alarion Province,Timbuktu Theater | AP11: LA,Alarion Province,Timbuktu Theater | AQ11: LA,Alarion Province,Timbuktu Theater,Buena Archonette | AR11: LA,Alarion Province,Timbuktu Theater,Buena Archonette | AS11: LA,Timbuktu Theater | AT11: LC,Timbuktu Theater | AU11: LC,Timbuktu Theater | AV11: LC,Timbuktu Theater | AW11: LC,Timbuktu Theater | AX11: LC,Florida Theater | AY11: LC,Florida Theater | AZ11: LC,Florida Theater
A12: 9 | B12: Abiy Adi | D12: {=index(systems,match($A12,INDEX(systems,0,1),),3)} -> 349.466 | E12: {=index(systems,match($A12,INDEX(systems,0,1),),4)} -> 314.567 | F12: =IFERROR(__xludf.DUMMYFUNCTION("let(row, match($B12&if($C12<>"""","" [""&$C12&""]"",""""),index(nebulae,,2),0),join("","",iferror(round(index(nebulae,row,5)/2,3),1),iferror(round(index(nebulae,row,6)/2,3),1),0))"),"1,1,0") -> 1,1,0 | G12: https://www.sarna.net/wiki/Abiy_Adi | H12: {=let(systemId,match(A12,index(systems,0,1),),refSystemId,match($H$1,index(systems,0,1),),x,index(systems,systemId,3),y,index(systems,systemId,4),refX,index(systems,refSystemId,3),refY,index(systems,refSystemId,4),round(sqrt((x-refX)^2+(y-refY)^2),3))} -> 470.19 | I12: U | J12: U | K12: U | L12: U | M12: U | N12: U | P12: DC,Pesht Military District,Ningxia Prefecture | Q12: DC,Pesht Military District,Ningxia Prefecture | R12: DC,Pesht Military District,Ningxia Prefecture | S12: DC,Pesht Military District,Ningxia Prefecture | T12: DC,Pesht Military District,Ningxia Prefecture | U12: DC,Pesht Military District,Ningxia Prefecture | V12: DC,Pesht Military District,Ningxia Prefecture | W12: DC,Pesht Military District,Ningxia Prefecture | X12: DC,Pesht Military District,Ningxia Prefecture | Y12: DC,Pesht Military District,Ningxia Prefecture | Z12: DC,Pesht Military District,Ningxia Prefecture | AA12: DC,Pesht Military District,Ningxia Prefecture | AB12: DC,Pesht Military District,Ningxia Prefecture | AC12: DC,Pesht Military District,Ningxia Prefecture | AD12: DC,Pesht Military District,Ningxia Prefecture | AE12: DC,Pesht Military District,Ningxia Prefecture | AF12: DC,Pesht Military District,Ningxia Prefecture | AG12: DC,Pesht Military District,Ningxia Prefecture | AH12: DC,Pesht Military District,Ningxia Prefecture | AI12: DC,Pesht Military District,Ningxia Prefecture | AJ12: DC,Pesht Military District,Ningxia Prefecture | AK12: DC,Pesht Military District,Ningxia Prefecture | AL12: DC,Pesht Military District,Ningxia Prefecture | AM12: DC,Pesht Military District,Ningxia Prefecture | AN12: DC,Pesht Military District,Ningxia Prefecture | AO12: DC,Pesht Military District,Ningxia Prefecture | AP12: DC,Pesht Military District,Ningxia Prefecture | AQ12: DC,Pesht Military District,Ningxia Prefecture | AR12: DC,Pesht Military District,Ningxia Prefecture | AS12: DC,Pesht Military District,Ningxia Prefecture | AT12: DC,Pesht Military District,Ningxia Prefecture | AU12: DC,Pesht Military District,Ningxia Prefecture | AV12: DC,Pesht Military District,Ningxia Prefecture | AW12: DC,Pesht Military District,Ningxia Prefecture | AX12: DC,Pesht Military District,Ningxia Prefecture | AY12: DC,Pesht Military District,Ningxia Prefecture | AZ12: DC,Pesht Military District,Ningxia Prefecture
A13: 3126 | B13: Able's Glory | D13: {=index(systems,match($A13,INDEX(systems,0,1),),3)} -> -539.232 | E13: {=index(systems,match($A13,INDEX(systems,0,1),),4)} -> 124.693 | F13: =IFERROR(__xludf.DUMMYFUNCTION("let(row, match($B13&if($C13<>"""","" [""&$C13&""]"",""""),index(nebulae,,2),0),join("","",iferror(round(index(nebulae,row,5)/2,3),1),iferror(round(index(nebulae,row,6)/2,3),1),0))"),"1,1,0") -> 1,1,0 | G13: https://www.sarna.net/wiki/Able's_Glory | H13: {=let(systemId,match(A13,index(systems,0,1),),refSystemId,match($H$1,index(systems,0,1),),x,index(systems,systemId,3),y,index(systems,systemId,4),refX,index(systems,refSystemId,3),refY,index(systems,refSystemId,4),round(sqrt((x-refX)^2+(y-refY)^2),3))} -> 553.461 | I13: U | J13: U | K13: U | L13: U | M13: U | N13: U | P13: U | Q13: U | R13: U | S13: U | T13: U | U13: U | V13: U | W13: U | X13: U | Y13: U | Z13: U | AA13: U | AB13: U | AC13: U | AD13: U | AE13: U | AF13: U | AG13: U | AH13: U | AI13: U | AJ13: U | AK13: U | AL13: U | AM13: U | AN13: U | AO13: U | AP13: U | AQ13: U | AR13: U | AS13: U | AT13: U | AU13: U | AV13: RC | AW13: RC | AX13: RC | AY13: TiC | AZ13: TiC
A14: 10 | B14: Aboukir | D14: {=index(systems,match($A14,INDEX(systems,0,1),),3)} -> -419.964 | E14: {=index(systems,match($A14,INDEX(systems,0,1),),4)} -> 287.637 | F14: =IFERROR(__xludf.DUMMYFUNCTION("let(row, match($B14&if($C14<>"""","" [""&$C14&""]"",""""),index(nebulae,,2),0),join("","",iferror(round(index(nebulae,row,5)/2,3),1),iferror(round(index(nebulae,row,6)/2,3),1),0))"),"1,1,0") -> 1,1,0 | G14: https://www.sarna.net/wiki/Aboukir | H14: {=let(systemId,match(A14,index(systems,0,1),),refSystemId,match($H$1,index(systems,0,1),),x,index(systems,systemId,3),y,index(systems,systemId,4),refX,index(systems,refSystemId,3),refY,index(systems,refSystemId,4),round(sqrt((x-refX)^2+(y-refY)^2),3))} -> 509.023 | I14: U | J14: U | K14: U | L14: U | M14: U | N14: U | P14: RW,Finmark Province | Q14: RW,Finmark Province | R14: RW,Finmark Province | S14: LC,Protectorate of Donegal,Coventry Province | T14: LC,Protectorate of Donegal,Coventry Province | U14: LC,Protectorate of Donegal,Coventry Province | V14: LC,Protectorate of Donegal,Coventry Province | W14: LC,Protectorate of Donegal,Coventry Province | X14: LC,Protectorate of Donegal,Coventry Province | Y14: A | Z14: A | AA14: A | AB14: A | AC14: A | AD14: A | AE14: A | AF14: A | AG14: A | AH14: A | AI14: A | AJ14: A | AK14: A | AL14: A | AM14: A | AN14: A | AO14: A | AP14: A | AQ14: A | AR14: A | AS14: A | AT14: A | AU14: A | AV14: A | AW14: A | AX14: A | AY14: A | AZ14: A
A15: 11 | B15: Abramkovo | D15: {=index(systems,match($A15,INDEX(systems,0,1),),3)} -> -330.86 | E15: {=index(systems,match($A15,INDEX(systems,0,1),),4)} -> -28.739 | F15: =IFERROR(__xludf.DUMMYFUNCTION("let(row, match($B15&if($C15<>"""","" [""&$C15&""]"",""""),index(nebulae,,2),0),join("","",iferror(round(index(nebulae,row,5)/2,3),1),iferror(round(index(nebulae,row,6)/2,3),1),0))"),"1,1,0") -> 1,1,0 | G15: https://www.sarna.net/wiki/Abramkovo | H15: {=let(systemId,match(A15,index(systems,0,1),),refSystemId,match($H$1,index(systems,0,1),),x,index(systems,systemId,3),y,index(systems,systemId,4),refX,index(systems,refSystemId,3),refY,index(systems,refSystemId,4),round(sqrt((x-refX)^2+(y-refY)^2),3))} -> 332.106 | I15: U | J15: U | K15: U | L15: U | M15: U | N15: U | P15: LC,Protectorate of Donegal,Alarion Province | Q15: LC,Protectorate of Donegal,Alarion Province | R15: LC,Protectorate of Donegal,Alarion Province | S15: LC,Protectorate of Donegal,Alarion Province | T15: LC,Protectorate of Donegal,Alarion Province | U15: LC,Protectorate of Donegal,Alarion Province | V15: LC,Protectorate of Donegal,Alarion Province | W15: LC,Protectorate of Donegal,Alarion Province | X15: LC,Protectorate of Donegal,Alarion Province | Y15: LC,Protectorate of Donegal,Alarion Province | Z15: LC,Protectorate of Donegal,Bolan Province | AA15: FCL,Tamarind March,Bolan Operational Area,Region 2 | AB15: FCL,Tamarind March,Bolan Operational Area,Region 2 | AC15: FCL,Tamarind March,Bolan Operational Area,Region 2 | AD15: FCL,Tamarind March,Bolan Operational Area,Region 2 | AE15: FCL,Tamarind March,Bolan Operational Area,Region 2 | AF15: FCL,Tamarind March,Bolan Operational Area,Region 2 | AG15: FCL,Tamarind March,Bolan Operational Area,Region 2 | AH15: LA,Tamarind March,Bolan Operational Area,Region 2 | AI15: LA,Bolan Province,Cavanaugh Theater | AJ15: LA,Bolan Province,Cavanaugh Theater | AK15: LA,Bolan Province,Cavanaugh Theater | AL15: LA,Bolan Province,Cavanaugh Theater | AM15: LA,Bolan Province,Cavanaugh Theater | AN15: LA,Bolan Province,Cavanaugh Theater | AO15: LA,Bolan Province,Cavanaugh Theater | AP15: LA,Bolan Province,Dixie Theater | AQ15: LA,Bolan Province,Dixie Theater | AR15: LA,Bolan Province,Dixie Theater | AS15: LA,Bolan Province,Dixie Theater | AT15: LC,Bolan Province,Dixie Theater | AU15: LC,Bolan Province,Dixie Theater | AV15: LC,Bolan Province,Cavanaugh Theater | AW15: LC,Bolan Province,Cavanaugh Theater | AX15: LC,Timbuktu Theater | AY15: FWL,Duchy of Tammarind-Abbey | AZ15: FWL,Duchy of Tammarind-Abbey
A16: 12 | B16: Abruzzi | D16: {=index(systems,match($A16,INDEX(systems,0,1),),3)} -> 149.392 | E16: {=index(systems,match($A16,INDEX(systems,0,1),),4)} -> -304.327 | F16: =IFERROR(__xludf.DUMMYFUNCTION("let(row, match($B16&if($C16<>"""","" [""&$C16&""]"",""""),index(nebulae,,2),0),join("","",iferror(round(index(nebulae,row,5)/2,3),1),iferror(round(index(nebulae,row,6)/2,3),1),0))"),"1,1,0") -> 1,1,0 | G16: https://www.sarna.net/wiki/Abruzzi | H16: {=let(systemId,match(A16,index(systems,0,1),),refSystemId,match($H$1,index(systems,0,1),),x,index(systems,systemId,3),y,index(systems,systemId,4),refX,index(systems,refSystemId,3),refY,index(systems,refSystemId,4),round(sqrt((x-refX)^2+(y-refY)^2),3))} -> 339.018 | I16: U | J16: U | K16: U | L16: U | M16: U | N16: U | P16: CC,St. Ives Commonality,Region 6 | Q16: CC,St. Ives Commonality,Region 6 | R16: CC,St. Ives Commonality,Region 6 | S16: CC,St. Ives Commonality,Region 6 | T16: CC,St. Ives Commonality,Region 6 | U16: CC,St. Ives Commonality,Region 6 | V16: CC,St. Ives Commonality,Region 6 | W16: CC,St. Ives Commonality,Region 6 | X16: FS,Capellan March,Taygeta Operational Area,Region 1 | Y16: FS,Capellan March,Taygeta Operational Area,Sirdar PDZ | Z16: FS,Capellan March,Taygeta Operational Area,Sirdar PDZ | AA16: FCF,Capellan March,Taygeta Operational Area,Sirdar PDZ | AB16: FCF,Capellan March,Taygeta Operational Area,Sirdar PDZ | AC16: FCF,Capellan March,Taygeta Operational Area,Sirdar PDZ | AD16: FCF,Capellan March,Taygeta Operational Area,Sirdar PDZ | AE16: FCF,Capellan March,Taygeta Operational Area,Sirdar PDZ | AF16: FCF,Capellan March,Taygeta Operational Area,Sirdar PDZ | AG16: FCF,Capellan March,Taygeta Operational Area,Sirdar PDZ | AH16: FCF,Capellan March,Taygeta Operational Area,Sirdar PDZ | AI16: FCF,Capellan March,Taygeta Operational Area,Sirdar PDZ | AJ16: FCF,Capellan March,Taygeta Operational Area,Sirdar PDZ | AK16: FCF,Capellan March,Taygeta Operational Area,Sirdar PDZ | AL16: FCF,Capellan March,Taygeta Operational Area,Sirdar PDZ | AM16: FCF,Capellan March,Taygeta Operational Area,Sirdar PDZ | AN16: FCF,Capellan March,Taygeta Operational Area,Sirdar PDZ | AO16: FS,Capellan March,Taygeta Operational Area,Sirdar PDZ | AP16: FS,Capellan March,Taygeta Operational Area,Sirdar PDZ | AQ16: FS,Capellan March,Taygeta Operational Area,Sirdar PDZ | AR16: FS,Capellan March,Taygeta Operational Area,Sirdar PDZ | AS16: FS,Capellan March,Taygeta Operational Area,Sirdar PDZ | AT16: FS,Capellan March,Taygeta Operational Area,Sirdar PDZ | AU16: FS,Capellan March,Taygeta Operational Area,Sirdar PDZ | AV16: FS,Capellan March,Taygeta Operational Area,Sirdar PDZ | AW16: FS,Capellan March,Taygeta Operational Area,Sirdar PDZ | AX16: FS,Capellan March,Sirdar Operational Area,Sirdar PDZ | AY16: FS,Capellan March,Taygeta Operational Area,Sirdar PDZ | AZ16: FS,Capellan March,Taygeta Operational Area,Sirdar PDZ
A17: 13 | B17: Abushiri | D17: {=index(systems,match($A17,INDEX(systems,0,1),),3)} -> -267.585 | E17: {=index(systems,match($A17,INDEX(systems,0,1),),4)} -> 326.475 | F17: =IFERROR(__xludf.DUMMYFUNCTION("let(row, match($B17&if($C17<>"""","" [""&$C17&""]"",""""),index(nebulae,,2),0),join("","",iferror(round(index(nebulae,row,5)/2,3),1),iferror(round(index(nebulae,row,6)/2,3),1),0))"),"1,1,0") -> 1,1,0 | G17: https://www.sarna.net/wiki/Abushiri | H17: {=let(systemId,match(A17,index(systems,0,1),),refSystemId,match($H$1,index(systems,0,1),),x,index(systems,systemId,3),y,index(systems,systemId,4),refX,index(systems,refSystemId,3),refY,index(systems,refSystemId,4),round(sqrt((x-refX)^2+(y-refY)^2),3))} -> 422.123 | I17: U | J17: U | K17: U | L17: U | M17: U | N17: U | P17: RW,Apollo Province | Q17: RW,Apollo Province | R17: RW,Apollo Province | S17: LC,Protectorate of Donegal,Coventry Province | T17: LC,Protectorate of Donegal,Coventry Province | U17: LC,Protectorate of Donegal,Coventry Province | V17: LC,Protectorate of Donegal,Coventry Province | W17: LC,Protectorate of Donegal,Coventry Province | X17: LC,Protectorate of Donegal,Coventry Province | Y17: A | Z17: A | AA17: A | AB17: A | AC17: A | AD17: A | AE17: A | AF17: A | AG17: A | AH17: A | AI17: A | AJ17: A | AK17: A | AL17: A | AM17: A | AN17: A | AO17: A | AP17: A | AQ17: A | AR17: A | AS17: A | AT17: A | AU17: A | AV17: A | AW17: A | AX17: A | AY17: A | AZ17: A
A18: 14 | B18: Acala | D18: {=index(systems,match($A18,INDEX(systems,0,1),),3)} -> 134.156 | E18: {=index(systems,match($A18,INDEX(systems,0,1),),4)} -> -124.34 | F18: =IFERROR(__xludf.DUMMYFUNCTION("let(row, match($B18&if($C18<>"""","" [""&$C18&""]"",""""),index(nebulae,,2),0),join("","",iferror(round(index(nebulae,row,5)/2,3),1),iferror(round(index(nebulae,row,6)/2,3),1),0))"),"1,1,0") -> 1,1,0 | G18: https://www.sarna.net/wiki/Acala | H18: {=let(systemId,match(A18,index(systems,0,1),),refSystemId,match($H$1,index(systems,0,1),),x,index(systems,systemId,3),y,index(systems,systemId,4),refX,index(systems,refSystemId,3),refY,index(systems,refSystemId,4),round(sqrt((x-refX)^2+(y-refY)^2),3))} -> 182.916 | J18: I | M18: FS | N18: CC,Sarna Commonality,Region 7 | O18: CC,Sarna Commonality,Region 7 | P18: CC,Sarna Commonality,Region 7 | Q18: CC,Sarna Commonality,Region 7 | R18: CC,Sarna Commonality,Region 7 | S18: CC,Sarna Commonality,Region 7 | T18: CC,Sarna Commonality,Region 7 | U18: CC,Sarna Commonality,Region 7 | V18: CC,Sarna Commonality,Region 7 | W18: CC,Sarna Commonality,Region 7 | X18: FS,Capellan March,Kathil Operational Area,Region 1 | Y18: FS,Capellan March,Kathil Operational Area,Valexa PDZ | Z18: FS,Capellan March,Kathil Operational Area,Valexa PDZ | AA18: FCF,Capellan March,Kathil Operational Area,Valexa PDZ | AB18: FCF,Capellan March,Kathil Operational Area,Valexa PDZ | AC18: FCF,Capellan March,Kathil Operational Area,Valexa PDZ | AD18: FCF,Capellan March,Kathil Operational Area,Valexa PDZ | AE18: FCF,Capellan March,Kathil Operational Area,Valexa PDZ | AF18: FCF,Capellan March,Kathil Operational Area,Valexa PDZ | AG18: FCF,Capellan March,Kathil Operational Area,Valexa PDZ | AH18: FCF,Capellan March,Kathil Operational Area,Valexa PDZ | AI18: FCF,Capellan March,Kathil Operational Area,Valexa PDZ | AJ18: FCF,Capellan March,Kathil Operational Area,Valexa PDZ | AK18: FCF,Capellan March,Kathil Operational Area,Valexa PDZ | AL18: FCF,Capellan March,Kathil Operational Area,Valexa PDZ | AM18: FCF,Capellan March,Kathil Operational Area,Valexa PDZ | AN18: FCF,Capellan March,Kathil Operational Area,Valexa PDZ | AO18: FS,Capellan March,Kathil Operational Area,Valexa PDZ | AP18: FS,Capellan March,Kathil Operational Area,Valexa PDZ | AQ18: FS,Capellan March,Kathil Operational Area,Valexa PDZ | AR18: FS,Capellan March,Kathil Operational Area,Valexa PDZ | AS18: FS,Capellan March,Kathil Operational Area,Valexa PDZ | AT18: FS,Capellan March,Kathil Operational Area,Valexa PDZ | AU18: FS,Capellan March,Kathil Operational Area,Valexa PDZ | AV18: FS,Capellan March,Kathil Operational Area,Alcyone PDZ | AW18: FS,Capellan March,Kathil Operational Area,Alcyone PDZ | AX18: FS,Capellan March,Kathil Operational Area,Alcyone PDZ | AY18: FS,Capellan March,Kathil Operational Area,Alcyone PDZ | AZ18: FS,Capellan March,Kathil Operational Area,Alcyone PDZ
A19: 15 | B19: Acamar | D19: {=index(systems,match($A19,INDEX(systems,0,1),),3)} -> 39.543 | E19: {=index(systems,match($A19,INDEX(systems,0,1),),4)} -> -38.565 | F19: =IFERROR(__xludf.DUMMYFUNCTION("let(row, match($B19&if($C19<>"""","" [""&$C19&""]"",""""),index(nebulae,,2),0),join("","",iferror(round(index(nebulae,row,5)/2,3),1),iferror(round(index(nebulae,row,6)/2,3),1),0))"),"1,1,0") -> 1,1,0 | G19: https://www.sarna.net/wiki/Acamar | H19: {=let(systemId,match(A19,index(systems,0,1),),refSystemId,match($H$1,index(systems,0,1),),x,index(systems,systemId,3),y,index(systems,systemId,4),refX,index(systems,refSystemId,3),refY,index(systems,refSystemId,4),round(sqrt((x-refX)^2+(y-refY)^2),3))} -> 55.235 | I19: I | L19: TH | M19: TH | N19: TH,Terra Firma Province | O19: TH,Terra Firma Province | P19: TH,Terra Firma Province | Q19: TH,Terra Firma Province | R19: AE,Terra Firma Province | S19: TH,Terra Firma Province | T19: TH,Brownsville Province | U19: CC,Tikonov Commonality,Region 3 | V19: CC,Tikonov Commonality,Region 3 | W19: CC,Tikonov Commonality,Region 3 | X19: CC,Tikonov Commonality,Region 3 | Y19: CC,Tikonov Commonality,Region 5 | Z19: TFR | AA19: FCL,Sarna March,Terra Firma Operational Area,Region 2 | AB19: FCL,Sarna March,Terra Firma Operational Area,Region 2 | AC19: FCL,Sarna March,Terra Firma Operational Area,Region 2 | AD19: FCL,Sarna March,Terra Firma Operational Area,Region 2 | AE19: FCL,Sarna March,Terra Firma Operational Area,Region 2 | AF19: FCL,Sarna March,Terra Firma Operational Area,Region 2 | AG19: FCL,Sarna March,Terra Firma Operational Area,Region 2 | AH19: I | AI19: I | AJ19: I | AK19: I | AL19: I | AM19: I | AN19: I | AO19: FS,Capellan March,Kathil Operational Area,Region 1 | AP19: WB | AQ19: WB | AR19: CoF | AS19: RS,Prefecture V | AT19: RS,Prefecture V | AU19: RS,Prefecture V | AV19: RS,Prefecture V | AW19: I | AX19: CC,Tikonov Commonality,Region 1 | AY19: CC,Tikonov Commonality,Region 6 | AZ19: CC,Tikonov Commonality,Region 6
